<?xml version="1.0" encoding="UTF-8"?>
<!-- Generated by org.testng.reporters.JUnitReportReporter -->
<testsuite hostname="kairosHW0423" failures="0" tests="4" name="api.test.Test_User" time="0.005" errors="1" timestamp="2024-05-21T12:42:51 IST" skipped="3">
  <testcase classname="api.test.Test_User" name="test_createUser" time="0.004">
    <error message="Cannot invoke &quot;java.lang.Throwable.getMessage()&quot; because the return value of &quot;org.testng.ITestResult.getThrowable()&quot; is null" type="java.lang.NullPointerException">
      <![CDATA[java.lang.NullPointerException: Cannot invoke "java.lang.Throwable.getMessage()" because the return value of "org.testng.ITestResult.getThrowable()" is null
at api.utilities.ListenerUtility.onTestStart(ListenerUtility.java:46)
at org.testng.internal.TestListenerHelper.runTestListeners(TestListenerHelper.java:115)
at org.testng.internal.invokers.TestInvoker.runTestResultListener(TestInvoker.java:263)
at org.testng.internal.invokers.TestInvoker.invokeMethod(TestInvoker.java:625)
at org.testng.internal.invokers.TestInvoker.invokeTestMethod(TestInvoker.java:228)
at org.testng.internal.invokers.MethodRunner.runInSequence(MethodRunner.java:63)
at org.testng.internal.invokers.TestInvoker$MethodInvocationAgent.invoke(TestInvoker.java:961)
at org.testng.internal.invokers.TestInvoker.invokeTestMethods(TestInvoker.java:201)
at org.testng.internal.invokers.TestMethodWorker.invokeTestMethods(TestMethodWorker.java:148)
at org.testng.internal.invokers.TestMethodWorker.run(TestMethodWorker.java:128)
at java.base/java.util.ArrayList.forEach(ArrayList.java:1511)
at org.testng.TestRunner.privateRun(TestRunner.java:819)
at org.testng.TestRunner.run(TestRunner.java:619)
at org.testng.SuiteRunner.runTest(SuiteRunner.java:443)
at org.testng.SuiteRunner.runSequentially(SuiteRunner.java:437)
at org.testng.SuiteRunner.privateRun(SuiteRunner.java:397)
at org.testng.SuiteRunner.run(SuiteRunner.java:336)
at org.testng.SuiteRunnerWorker.runSuite(SuiteRunnerWorker.java:52)
at org.testng.SuiteRunnerWorker.run(SuiteRunnerWorker.java:95)
at org.testng.TestNG.runSuitesSequentially(TestNG.java:1301)
at org.testng.TestNG.runSuitesLocally(TestNG.java:1228)
at org.testng.TestNG.runSuites(TestNG.java:1134)
at org.testng.TestNG.run(TestNG.java:1101)
at org.testng.remote.AbstractRemoteTestNG.run(AbstractRemoteTestNG.java:115)
at org.testng.remote.RemoteTestNG.initAndRun(RemoteTestNG.java:251)
at org.testng.remote.RemoteTestNG.main(RemoteTestNG.java:77)
]]>
    </error>
  </testcase> <!-- test_createUser -->
  <testcase classname="api.test.Test_User" name="test_getUser" time="0.000">
    <skipped/>
  </testcase> <!-- test_getUser -->
  <testcase classname="api.test.Test_User" name="test_putUser" time="0.000">
    <skipped/>
  </testcase> <!-- test_putUser -->
  <testcase classname="api.test.Test_User" name="test_deleteUser" time="0.001">
    <skipped/>
  </testcase> <!-- test_deleteUser -->
</testsuite> <!-- api.test.Test_User -->
